<?xml version="1.0" encoding="utf-8"?>
<!-- This URDF was automatically created by SolidWorks to URDF Exporter! Originally created by Stephen Brawner (brawner@gmail.com) 
     Commit Version: 1.6.0-4-g7f85cfe  Build Version: 1.6.7995.38578
     For more information, please see http://wiki.ros.org/sw_urdf_exporter -->
<robot name="myrobot" xmlns:xacro="http://www.ros.org/wiki/xacro">

<xacro:include filename="$(find myrobot)/urdf/diffrobot.gazebo"/>

<link name="base_footprint">  
</link>

<joint name="base_footprint_joint" type="fixed">
      <origin
        xyz="-0.00878802986272705 0.00182751727792896 0.3"
        rpy="0 0 0" />
    <parent link ="base_footprint"/>
    <child link ="base_link"/>   
</joint>
<link
    name="base_link">
    <inertial>
      <origin
        xyz="-0.00878802986272705 0.00182751727792896 0.218440349920027"
        rpy="0 0 0" />
      <mass
        value="3.5" />
      <inertia
        ixx="0.0320086345792064"
        ixy="-0.00197157657713284"
        ixz="7.34849110229213E-05"
        iyy="0.0280608922122791"
        iyz="-8.40485415229841E-06"
        izz="0.0311815506700615" />
    </inertial>
    <visual>
      <origin
        xyz="0 0 0"
        rpy="0 0 0" />
      <geometry>
        <mesh
          filename="package://myrobot/meshes/base_link.STL" />
      </geometry>
      <material
        name="">
        <color
          rgba="0.752941176470588 0.752941176470588 0.752941176470588 1" />
      </material>
    </visual>
    <collision>
      <origin
        xyz="0 0 0"
        rpy="0 0 0" />
      <geometry>
        <mesh
          filename="package://myrobot/meshes/base_link.STL" />
      </geometry>
    </collision>
  </link>
  <link
    name="right_wheel">
    <inertial>
      <origin
        xyz="-0.00344741998003394 -2.1108081948995E-10 -0.01131387738546"
        rpy="0 0 0" />
      <mass
        value="3.000161240003184" />
      <inertia
        ixx="0.000181530632659706"
        ixy="1.02129176407146E-08"
        ixz="4.07602070316519E-05"
        iyy="0.000169122553864932"
        iyz="-3.11141612020601E-09"
        izz="0.000302879141808666" />
    </inertial>
    <visual>
      <origin
        xyz="0 0 0"
        rpy="0 0 0" />
      <geometry>
        <mesh
          filename="package://myrobot/meshes/right_wheel.STL" />
      </geometry>
      <material
        name="">
        <color
          rgba="0.752941176470588 0.752941176470588 0.752941176470588 1" />
      </material>
    </visual>
    <collision>
      <origin
        xyz="0 0 0"
        rpy="0 0 0" />
      <geometry>
        <mesh
          filename="package://myrobot/meshes/right_wheel.STL" />
      </geometry>
    </collision>
  </link>
  <joint
    name="right_wheel_joint"
    type="continuous">
    <origin
      xyz="0.050607 0.19411 -0.23937"
      rpy="-1.5708 0 0" />
    <parent
      link="base_link" />
    <child
      link="right_wheel" />
    <axis
      xyz="0.29148 0 0.95658" />
  </joint>
  <link
    name="left_wheel">
    <inertial>
      <origin
        xyz="0.00344742087625166 1.5232703987067E-10 0.0113138811679357"
        rpy="0 0 0" />
      <mass
        value="3.000161251952286" />
      <inertia
        ixx="0.000181530636691592"
        ixy="1.02134764661581E-08"
        ixz="4.07602057616038E-05"
        iyy="0.000169122553856326"
        iyz="-3.11156872034025E-09"
        izz="0.000302879142409888" />
    </inertial>
    <visual>
      <origin
        xyz="0 0 0"
        rpy="0 0 0" />
      <geometry>
        <mesh
          filename="package://myrobot/meshes/left_wheel.STL" />
      </geometry>
      <material
        name="">
        <color
          rgba="0.752941176470588 0.752941176470588 0.752941176470588 1" />
      </material>
    </visual>
    <collision>
      <origin
        xyz="0 0 0"
        rpy="0 0 0" />
      <geometry>
        <mesh
          filename="package://myrobot/meshes/left_wheel.STL" />
      </geometry>
    </collision>
  </link>
  <joint
    name="left_wheel_joint"
    type="continuous">
    <origin
      xyz="-0.068169 -0.1957 -0.23937"
      rpy="-1.5708 0 0" />
    <parent
      link="base_link" />
    <child
      link="left_wheel" />
    <axis
      xyz="0.29148 0 0.95658" />
  </joint>
  <link
    name="front_caster_body">
    <inertial>
      <origin
        xyz="0.00344237029250091 -0.00536115882907073 -0.0109426197234808"
        rpy="0 0 0" />
      <mass
        value="0.00337916710823925" />
      <inertia
        ixx="2.96991791195796E-07"
        ixy="-2.59280805250604E-08"
        ixz="3.51578915679416E-08"
        iyy="3.26974921471009E-07"
        iyz="-5.47894238134561E-08"
        izz="3.00884092061423E-07" />
    </inertial>
    <visual>
      <origin
        xyz="0 0 0"
        rpy="0 0 0" />
      <geometry>
        <mesh
          filename="package://myrobot/meshes/front_caster_body.STL" />
      </geometry>
      <material
        name="">
        <color
          rgba="0.792156862745098 0.819607843137255 0.933333333333333 1" />
      </material>
    </visual>
    <collision>
      <origin
        xyz="0 0 0"
        rpy="0 0 0" />
      <geometry>
        <mesh
          filename="package://myrobot/meshes/front_caster_body.STL" />
      </geometry>
    </collision>
  </link>

  <joint
    name="front_caster_body_joint"
    type="fixed">
    <origin
      xyz="0.15866 -0.047896 -0.26237"
      rpy="0 0 0" />
    <parent
      link="base_link" />
    <child
      link="front_caster_body" />
    <axis
      xyz="0 0 0" />
  </joint>
  <link
    name="front_caster">
    <inertial>
      <origin
        xyz="5.42009331860882E-09 5.9173497213294E-09 -8.20842027682289E-09"
        rpy="0 0 0" />
      <mass
        value="0.00383084780430772" />
      <inertia
        ixx="1e-06"
        ixy="0"
        ixz="0"
        iyy="1e-06"
        iyz="0"
        izz="1e-06" />
    </inertial>
    <visual>
      <origin
        xyz="0 0 0"
        rpy="0 0 0" />
      <geometry>
        <mesh
          filename="package://myrobot/meshes/front_caster.STL" />
      </geometry>
      <material
        name="">
        <color
          rgba="0.792156862745098 0.819607843137255 0.933333333333333 1" />
      </material>
    </visual>
    <collision>
      <origin
        xyz="0 0 0"
        rpy="0 0 0" />
      <geometry>
        <mesh
          filename="package://myrobot/meshes/front_caster.STL" />
      </geometry>
    </collision>
  </link>
  <joint
    name="front_caster__joint"
    type="fixed">
    <origin
      xyz="0.0076289 -0.011804 -0.026766"
      rpy="-1.5708 0 0" />
    <parent
      link="front_caster_body" />
    <child
      link="front_caster" />
    <axis
      xyz="0 0 0" />
  </joint>
  <link
    name="back_caster_body">
    <inertial>
      <origin
        xyz="-0.00344237029250025 0.00536115882907057 -0.010942619723481"
        rpy="0 0 0" />
      <mass
        value="0.00337916710823945" />
      <inertia
        ixx="2.96991791195826E-07"
        ixy="-2.59280805250485E-08"
        ixz="-3.51578915679579E-08"
        iyy="3.26974921471047E-07"
        iyz="5.47894238134673E-08"
        izz="3.00884092061452E-07" />
    </inertial>
    <visual>
      <origin
        xyz="0 0 0"
        rpy="0 0 0" />
      <geometry>
        <mesh
          filename="package://myrobot/meshes/back_caster_body.STL" />
      </geometry>
      <material
        name="">
        <color
          rgba="0.792156862745098 0.819607843137255 0.933333333333333 1" />
      </material>
    </visual>
    <collision>
      <origin
        xyz="0 0 0"
        rpy="0 0 0" />
      <geometry>
        <mesh
          filename="package://myrobot/meshes/back_caster_body.STL" />
      </geometry>
    </collision>
  </link>
  <joint
    name="back_caster_body_joint"
    type="fixed">
    <origin
      xyz="-0.17404 0.053481 -0.26237"
      rpy="0 0 0" />
    <parent
      link="base_link" />
    <child
      link="back_caster_body" />
    <axis
      xyz="0 0 0" />
  </joint>
  <link
    name="back_caster">
    <inertial>
      <origin
        xyz="-5.42009326309767E-09 5.9173498323517E-09 8.20842033233404E-09"
        rpy="0 0 0" />
      <mass
        value="0.00383084780430784" />
      <inertia
        ixx="1e-06"
        ixy="0"
        ixz="0"
        iyy="1e-06"
        iyz="0"
        izz="1e-06" />
    </inertial>
    <visual>
      <origin
        xyz="0 0 0"
        rpy="0 0 0" />
      <geometry>
        <mesh
          filename="package://myrobot/meshes/back_caster.STL" />
      </geometry>
      <material
        name="">
        <color
          rgba="0.792156862745098 0.819607843137255 0.933333333333333 1" />
      </material>
    </visual>
    <collision>
      <origin
        xyz="0 0 0"
        rpy="0 0 0" />
      <geometry>
        <mesh
          filename="package://myrobot/meshes/back_caster.STL" />
      </geometry>
    </collision>
  </link>
  <joint
    name="back_caster_joint"
    type="fixed">
    <origin
      xyz="-0.0076289 0.011804 -0.026766"
      rpy="-1.5708 0 0" />
    <parent
      link="back_caster_body" />
    <child
      link="back_caster" />
    <axis
      xyz="0 0 0" />
  </joint>



  <link name="lidar_link">
    <inertial>
        <origin xyz="0.0 0.0 0.0" rpy="0.0 0.0 0.0"/>
        <mass value="0.1"/>
        <inertia ixx="1.0" ixy="0.0" ixz="0.0" iyy="1.0" iyz="0.0" izz="1.0"/>
    </inertial>
    <visual name="lidar_link_visual">
        <origin xyz="0.0 0.0 0.0" rpy="0.0 0.0 0.0"/>
        <geometry>
       <mesh filename="package://myrobot/meshes/lidar_link.STL"/>     
          </geometry>
        <material name="">
            <color rgba="0.0 0.0 0.0 1.0"/>
            <texture filename=""/>
        </material>
    </visual>
    <collision>
        <origin xyz="0.0 0.0 0.0" rpy="0.0 0.0 0.0"/>
        <geometry>
            <box size="0.1 0.1 0.1"/>
        </geometry>
    </collision>
</link>

<joint name="lidar_joint" type="fixed">
 <origin xyz="0.08 -0.09 -0.07" rpy="1.57079632679491 0.0 1.57079632679491"/>
  <parent link="base_link"/>
    <child link="lidar_link"/>
    <axis xyz="0.0 0.0 0.0"/>
    <limit lower="0.0" upper="0.0" effort="0.0" velocity="0.0"/>
</joint>

    <link name="laser_data_link">
        
    </link>

    <joint name="laser_data_joint" type="fixed">

        <origin xyz="0.03 0.08 0.12" rpy="0.0 -1.5708 -1.5708"/> 
        <parent link="lidar_link"/>
        <child link="laser_data_link"/>
    </joint>



    
  
    <link name="camera_link">
      <inertial>
          <origin xyz="0.0 0.0 0.0" rpy="0.0 0.0 0.0"/>
          <mass value="0"/>
          <inertia ixx="0.0" ixy="0.0" ixz="0.0" iyy="0.0" iyz="0.0" izz="0.0"/>
      </inertial>
      <visual name="camera_link_visual">
          <origin xyz="0.0 0.0 0.0" rpy="0.0 0.0 1.5708"/>
          <geometry>
           <mesh filename="package://myrobot/meshes/kinect.dae"/>
            </geometry>
           <material name="">
              <color rgba="0.0 0.0 0.0 1.0"/>
              <texture filename=""/>
          </material>
          
      </visual>
      <collision>
          <origin xyz="0.0 0.0 0.0" rpy="0.0 0.0 0.0"/>
          <geometry>
              <box size="0.1 0.1 0.1"/>
          </geometry>
      </collision>
  </link>
  <joint name="camera_joint" type="fixed">
   <origin xyz="0.08 0 0.9" rpy="0 0 0"/>
    <parent link="base_link"/>
      <child link="camera_link"/>
      <axis xyz="0.0 0.0 0.0"/>
      <limit lower="0.0" upper="0.0" effort="0.0" velocity="0.0"/>
  </joint>
  <link name="camera_link_optical">
    
  </link>
    <joint name="camera_optical_joint" type="fixed">
          <parent link="camera_link"/>
          <child link="camera_link_optical"/>
          <origin xyz="0 0 0" rpy="-1.5708  0.0 -1.5708"/>
      </joint>  
  
</robot>
